Workbook

Sheet 00_阅读说明
A1: 单人动作验证与合作设计基线
A2: 本文件是开发规格，不是已完成报告。用户确认、策划提案和待验证假设分开管理。所有测试结果保持空白，所有任务默认未开始。
A3: YOU ARE CHALLENGER / P0 单人验证 / v0.1 / 2026-09-06
A5: 编号 | B5: 项目 | C5: 说明 | D5: 决策属性
A6: OV-01 | B6: 仓库 | C6: GcMin/you-are-challenger；本游戏独立于医院、太空及2d-bossrush-dungeon项目。 | D6: 用户确认
A7: OV-02 | B7: 目标 | C7: Godot 4.7.2 / GDScript 为用户指定目标；实际引擎版本须在仓库与运行环境核验。本文件不假设某个未核验版本的新API。 | D7: 用户指定
A8: OV-03 | B8: 一句话定位 | C8: 被指定的挑战者在八角笼中与Boss周旋；其余玩家选择协战、外围搜集和救援。混搭武器提供表现差异。 | D8: 已确认核心
A9: OV-04 | B9: 当前验证目标 | C9: 只优先完成一个可操控角色、一个有完整胜负流程的Boss、单人两次复活、战后自由搜刮与中央继承箱。 | D9: 用户确认＋范围收敛
A10: OV-05 | B10: 乐趣判断 | C10: 首要价值来自看懂攻击、做出选择、躲开并反击；外围搜集和交接属于合作差异化，不能由单人测试证明。 | D10: 策划判断
A11: OV-06 | B11: 最新覆盖：箱子 | C11: 战斗期间不出现；击败Boss并结束战斗后，在场地中央出现。失败后进入失败界面，不发放通关继承奖励。 | D11: 出现时机用户确认；失败分支为提案
A12: OV-07 | B12: 最新覆盖：搜刮 | C12: 击败Boss后不限制搜刮；不冻结地面物品，不以消失、封路、装箱倒计时迫使玩家战中搜刮。 | D12: 用户确认
A13: OV-08 | B13: 外围动机 | C13: 提议外围产出可选择时机使用的控场支援道具，使战中搜集换来当前Boss战的生存与反击窗口；不是更多枪械或弹药。 | D13: 新增提案，未获用户确认
A14: OV-09 | B14: P0不证明什么 | C14: 不证明多人协作、场外搜集收益、人数血量倍率、跨Boss构筑、隐藏Boss门槛或长期金币经济。 | D14: 验证边界
A15: OV-10 | B15: 真实实施状态 | C15: 代码现状需由开发者读取仓库核对；不得把本表计划、占位值或模拟值报告为已经实现或实测。 | D15: 治理规则
A16: OV-11 | B16: 推荐阅读顺序 | C16: 规则台账 → 乐趣与范围 → 单人流程 → 操控与Boss → 物品与箱子 → 任务与验收；外围支援留作P1实验。 | D16: 使用说明
A17: OV-12 | B17: P0结束条件 | C17: 可连续重开并完整经历胜利、超时失败、复活耗尽失败；手感问题可通过试玩数据定位；中央箱子容量和数据快照正确。 | D17: 验收目标
A20: 01_规则台账 | B20: 规则台账与旧方案覆盖 | D20: 28 条记录
A21: 02_乐趣与范围 | B21: 乐趣假设与P0范围 | D21: 15 条记录
A22: 03_单人流程 | B22: 一个Boss的完整单人流程 | D22: 12 条记录
A23: 04_角色操控 | B23: 角色操控规格与手感边界 | D23: 14 条记录
A24: 05_Boss规格 | B24: 验证Boss：擂台重锤手 | D24: 14 条记录
A25: 06_外围支援提案 | B25: 外围搜集提案：可择机使用的控场支援 | D25: 14 条记录
A26: 07_物品与箱子 | B26: 物品、战后自由搜刮与共享继承箱 | D26: 14 条记录
A27: 08_开发任务 | B27: 按可玩结果拆分的开发任务 | D27: 19 条记录
A28: 09_验收用例 | B28: 核心验收用例 | D28: 22 条记录
A29: 10_试玩记录 | B29: 试玩记录：只填真实观察 | D29: 20 条记录
A30: 11_参数与进度 | B30: 调参入口与验证进度 | D30: 45 条记录
A31: 12_决策与变更 | B31: 待决策项、覆盖记录与文档维护 | D31: 14 条记录

Sheet 01_规则台账
A1: 规则台账与旧方案覆盖
A2: “用户确认”是约束；“策划提案”允许试玩推翻。不得再恢复战中箱子、战后锁物资、多人复活预算或先制作多Boss。
A3: YOU ARE CHALLENGER / P0 单人验证 / v0.1 / 2026-09-06
A4: 返回目录
A5: ID | B5: 主题 | C5: 规则 | D5: 属性 | E5: 本版处理 | F5: 来源
A6: R01 | B6: 项目形态 | C6: 低多边形3D、第三人称、八角笼不封顶、周围看台。 | D6: 用户确认 | E6: P0灰模比例，观众静态占位 | F6: 本会话初始需求
A7: R02 | B7: 引擎目标 | C7: Godot 4.7.2 / GDScript。 | D7: 用户指定 | E7: 实施前核验实际可用版本，不虚构版本特性 | F7: 本会话初始需求
A8: R03 | B8: 挑战者 | C8: Boss指定一名挑战者；挑战者不得离笼。 | D8: 用户确认 | E8: P0只有自己；挑战期间阻止走出或翻滚越界 | F8: 本会话初始需求
A9: R04 | B9: 协作自由 | C9: 非挑战者可留场战斗或外围搜集。 | D9: 用户确认 | E9: P1联机验证，P0不制作AI队友 | F9: 本会话初始需求
A10: R05 | B10: 个人栏位 | C10: 一把武器、两个道具栏。 | D10: 用户确认 | E10: 不通过额外背包绕过限制 | F10: 上一轮明确
A11: R06 | B11: 弹药 | C11: 不设计弹药。 | D11: 用户确认 | E11: 不做弹匣、装填、弹药掉落，也不换名引入充能弹药 | F11: 上一轮明确
A12: R07 | B12: 精力 | C12: 引入精力条，翻滚有无敌帧。 | D12: 用户确认 | E12: P0翻滚和重攻击耗精力，具体参数为建议 | F12: 本会话修订
A13: R08 | B13: 单人复活 | C13: 整轮Boss Rush共有两次复活机会，非每个Boss重置。 | D13: 用户确认 | E13: P0一个Boss；新一轮才重置，继承测试不刷新 | F13: 本会话修订
A14: R09 | B14: 多人救援 | C14: 无复活次数；倒地由其他玩家救起。 | D14: 用户确认 | E14: P1，不能保留旧的自动或付费复活逻辑 | F14: 本会话修订
A15: R10 | B15: 交接 | C15: 挑战者倒下立即选下一名存活玩家，五秒后场外强制入场、场内继承身份。 | D15: 用户确认 | E15: 随即不解释成随机；选取算法另议 | F15: 本会话修订
A16: R11 | B16: 战斗时限 | C16: 每场Boss有时间限制。 | D16: 用户确认 | E16: P0超时判负建议；不同时增加复杂狂暴机制 | F16: 本会话修订
... A33: R28 | B33: 多人上限 | C33: 尚未由用户最终确定。 | D33: 待决策 | E33: P1先双人验证；不把4人写成正式上限 | F33: 本会话未明确

Sheet 02_乐趣与范围
A1: 乐趣假设与P0范围
A2: 单人P0只检验动作基础。合作交接和外围搜集是未来差异化，不应凭单机通关宣称已经验证。
A3: YOU ARE CHALLENGER / P0 单人验证 / v0.1 / 2026-09-06
A4: 返回目录
A5: ID | B5: 假设/功能 | C5: 具体决策或体验 | D5: P0处理 | E5: 验证方式/失败征兆
A6: F01 | B6: 可读攻击→成功闪避→反击 | C6: 玩家能从动作而非只看提示UI判断何时翻滚；反击来自Boss实际收招。 | D6: 核心必做 | E6: 回放或访谈能解释受伤原因；若只能记秒表或连续滚动，需重做节奏
A7: F02 | B7: 攻击承诺与精力 | C7: 短窗口轻击，大窗口重击；贪刀会来不及防守，保留精力可应对下一次攻击。 | D7: 核心必做 | E7: 比较轻击、重击、翻滚是否各有使用时机；不能一个动作永久压制
A8: F03 | B8: 空间取舍 | C8: 追击Boss、等他靠近、绕开正面、去空投点取补给，需要选择时机。 | D8: 必做空投与三招 | E8: 若只贴身转圈或一直后退即可无脑通关，修正攻击组合与射程
A9: F04 | B9: 战后整理 | C9: 自由搜刮全部遗留物品后，用两格箱子选择跨关保留内容。 | D9: 必做基本交互 | E9: P0证明功能，不宣称一个Boss已经证明长期构筑深度
A10: F05 | B10: 外围搜集即时支援 | C10: 牺牲一段协战时间，换来适时控场与反击窗口。 | D10: P1设计，不作P0必须 | E10: 双人比较全员协战/择机搜集；若所有局面固定跑腿或无人外出，则假设失败
A11: F06 | B11: 五秒身份交接与救援 | C11: 玩家准备接班，队伍决定先救人还是继续输出。 | D11: P1联机 | E11: 单人不能验证，禁止使用假队友脚本当多人结论
A12: F07 | B12: 荒诞武器与观众表现 | C12: 大剑、折凳、魔法和枪械混搭，观众对失误和成功动作反馈。 | D12: 美术方向保留；P0不堆内容 | E12: 画风与演出是增强项，不替代战斗可读性
A13: S01 | B13: 必须：操控 | C13: 移动、第三人称镜头、转向、轻重攻击、翻滚、精力、受击、交互。 | D13: P0-1 | E13: 一把双手大剑；占位动画可用但时序和命中必须可信
A14: S02 | B14: 必须：一只Boss | C14: 三种清晰招式、生命、伤害、攻击节奏、收招、胜败。 | D14: P0-2 | E14: 同一模型单阶段即可；不制作第二只或隐藏Boss
A15: S03 | B15: 必须：完整单人局 | C15: 准备→战斗→两次复活→胜利/失败→自由搜刮→中央箱→结果→重开。 | D15: P0-3 | E15: 新开一轮可靠重置；复活不重开整场
A16: S04 | B16: 必须：基本物资 | C16: 一把大剑、恢复药、精力饮料；单人空投，战后外围可拾取。 | D16: P0-3 | E16: 两类物品足够测试栏位；不新增弹药或耐久
... A20: S08 | B20: 明确不做 | C20: AI队友、随机地图、职业、词条品质、弹药、耐久、堆叠背包、观众AI、匹配大厅。 | D20: 本版排除 | E20: 有新增需求必须替换等量P0范围或进入后续候选

Sheet 03_单人流程
A1: 一个Boss的完整单人流程
A2: 一场Boss即本次验证用的整轮。跨关通过快照往返测试验证数据，不新增第二只Boss或完整连战来扩大范围。
A3: YOU ARE CHALLENGER / P0 单人验证 / v0.1 / 2026-09-06
A4: 返回目录
A5: 状态 | B5: 进入条件 | C5: 玩家可做什么 | D5: 系统行为 | E5: 退出条件/验收
A6: 准备 | B6: 启动或重新开始一轮 | C6: 移动、试挥武器、配置两个道具栏，按开始。 | D6: 生命精力满；整轮剩余复活=2；Boss不攻击；中央继承箱不存在。 | E6: 确认开始后进入战斗，计时从可控制的战斗开始点启动。
A7: 战斗 | B7: 玩家确认开始 | C7: 走位、轻重击、翻滚、用药、拾取空投。 | D7: 玩家为唯一挑战者；笼边阻止越界；BossAI与计时启用；箱子不生成。 | E7: Boss先死亡则胜利；玩家倒地且Boss存活则倒地分支；时间归零且Boss存活则失败。
A8: 空投 | B8: 战斗状态达到随机间隔 | C8: 观察落点；选择立即去拿或继续输出。 | D8: 合法落点显示提示后道具落地；未拾物资保留，有限总量；新掉落不能成为必需通关键。 | E8: 进入可拾取状态，战后仍可拾取。
A9: 单人倒地 | B9: 生命归零，Boss仍存活 | C9: 暂时不能攻击移动；看到剩余复活与恢复提示。 | D9: 若剩余机会>0消耗1次；Boss保留已损失生命；战斗时钟继续；移除已结算玩家攻击。 | E9: 短暂过渡后安全点复起；若没有机会则失败。
A10: 单人复起 | B10: 倒地分支已扣除机会 | C10: 恢复控制，选择移动躲招或主动进攻。 | D10: 恢复建议50%生命和满精力；短暂保护，主动攻击时提前结束；Boss不瞬移贴脸重击。 | E10: 回到同一场战斗；不能重置Boss和总计时。
A11: 胜利锁定 | B11: Boss生命归零 | C11: 击败演出结束后恢复自由移动。 | D11: 停止战斗计时和新空投；关闭Boss伤害与残留攻击；解除挑战者禁出；中央生成一个箱子。 | E11: 进入无限时搜刮整备，不立即切关。
A12: 自由搜刮 | B12: 已胜利 | C12: 离笼搜刮外围、拾取落地物资、替换武器、使用道具、存取中央箱。 | D12: 不封路、不清物、不限制搜刮时长；栏位与箱容量仍生效。 | E12: 玩家主动按结算/结束本轮；不是物品自动消失触发。
A13: 装箱确认 | B13: 玩家主动结束整备 | C13: 查看两格箱和未装箱物品提示，可取消返回。 | D13: 按照箱内清单建立快照；装箱不看物品来源；未入箱不默认为跨关。 | E13: 确认后保存本轮结果和继承测试快照。
A14: 结果 | B14: 确认装箱或战斗失败 | C14: 查看胜负、战斗用时、受击、使用复活次数；重新开始。 | D14: P0不发放未经设计的永久数值奖励；失败不生成通关继承奖励。 | E14: 重新开始新一轮时才恢复两次复活。
A15: 超时失败 | B15: 计时到零且Boss未死 | C15: 查看超时原因、选择重开。 | D15: 停AI、停止伤害与新空投；不生成胜利箱；保留结果日志。 | E15: 新一轮完全重置状态。
A16: 复活耗尽失败 | B16: 0机会时再次倒地，Boss未死 | C16: 查看失败原因、选择重开。 | D16: 两次复活意味着至多第三次倒地结束；此前复起不另开局。 | E16: 新一轮完全重置状态。
A17: 快照往返测试 | B17: 在调试入口读取装箱快照 | C17: 取回箱内物品，比较ID、数量、栏位。 | D17: 只测试序列化和恢复；不把此入口当第二关，不发奖励，不消耗或刷新本轮复活。 | E17: 还原物品与快照一一相符；可独立清除测试快照。

Sheet 04_角色操控
A1: 角色操控规格与手感边界
A2: 键位与数值是可调原型建议，不是用户已确认。优先稳定的命中反馈、镜头可读性和可解释的失败。
A3: YOU ARE CHALLENGER / P0 单人验证 / v0.1 / 2026-09-06
A4: 返回目录
A5: ID | B5: 功能/输入建议 | C5: 行为规格 | D5: 约束与反馈 | E5: 验收重点
A6: PC01 | B6: WASD移动 | C6: 相对镜头水平朝向移动；普通移动不耗精力。 | D6: 斜向不额外加速；受击或翻滚由状态控制，不能互相叠加造成瞬移。 | E6: 移动停止可控，无明显漂移；不因帧率不同改变位移。
A7: PC02 | B7: 鼠标镜头 | C7: 可水平旋转、限制俯仰；镜头碰到围栏/地面时保持人物与Boss可见。 | D7: 不把笼网当永远遮挡的实心墙；遮挡可用淡化或适当剔除。 | E7: 绕笼边一圈及贴墙战斗时可以辨认攻击预备动作。
A8: PC03 | B8: 朝向与辅助 | C8: 移动时角色朝向移动方向；攻击时允许朝前方近目标有限修正。 | D8: 不在攻击生效瞬间180度吸附；P0先不做复杂锁定目标系统。 | E8: 轻击命中朝向容易理解，落空原因可见。
A9: PC04 | B9: 左键轻击 | C9: 单段基础斩击，低承诺；第一版不需要三段连击树。 | D9: 轻击消耗10精力；忙碌连点不排队；伤害与动画共用状态时钟，同目标每击一次。 | E9: 命中和落空均按同一动作时序；不隔笼命中。
A10: PC05 | B10: 右键重击 | C10: 更长前摇与收招，伤害较高，消耗精力。 | D10: 攻击已进入生效阶段不能随时免费取消；前摇可给少量翻滚取消窗口。 | E10: 大收招窗口重击更合适；乱用会错失躲避机会。
A11: PC06 | B11: 空格翻滚 | C11: 当前移动方向翻滚，无方向输入时向角色前方；仅部分时段无敌。 | D11: 滚动0.55秒，起身收势0.05秒；起身无无敌且禁攻击/翻滚，精力不足拒绝。 | E11: 提前滚、正确滚、过晚滚呈现不同结果，无整段永久无敌。
A12: PC07 | B12: Shift冲刺 | C12: 可选，未完成核心手感前不作为必做；没有冲刺也可正常接近Boss。 | D12: 若加入则持续耗精力；不制作跳跃攀爬支线。 | E12: 不能无限冲刺绕圈使Boss永久失去攻击机会。
A13: PC08 | B13: 精力恢复 | C13: 停止耗精力一段时间后恢复，普通移动可恢复。 | D13: 耗尽仍能移动和恢复；轻击10、重击20、翻滚25精力，不足均不能执行。 | E13: 避免耗尽后同时失去移动、攻击和恢复而只能等死。
A14: PC09 | B14: E交互 | C14: 拾取或与箱子交互；只有一个当前高亮目标。 | D14: 武器替换会把旧武器放到地面；道具栏满时明确提示替换目标。 | E14: 不会凭空删除旧物或同一物品重复拾取。
A15: PC10 | B15: 1/2道具栏 | C15: 使用对应栏位道具；消耗后空出该栏。 | D15: 无额外背包；药品作用和消耗量可见；满生命时建议阻止误用。 | E15: 恢复生效一次，数量不负数。
A16: PC11 | B16: 受击反馈 | C16: 短暂受击动作、声音和方向提示，生命条扣减对应伤害。 | D16: 相同攻击不得因多碰撞体或每帧检测重复结算；必要时短受击保护防重叠连杀。 | E16: 玩家能判断由哪一招命中；日志记录attack_id。
... A19: PC14 | B19: 状态边界 | C19: 移动、攻击、翻滚、受击、倒地、交互状态互斥优先级明确。 | D19: 死亡取消伤害生效；暂停或结果界面不继续扣血；无需为P0搭建庞大架构。 | E19: 不出现倒地挥剑、复活重复扣次数、胜利后继续被攻击。

Sheet 05_Boss规格
A1: 验证Boss：铁卫双手大剑
A2: 一个双足近战Boss，单阶段、三种攻击。不依赖精细美术才能辨认动作；所有伤害、时间与距离均为测试初值。
A3: YOU ARE CHALLENGER / P0 单人验证 / v0.1 / 2026-09-06
A4: 返回目录
A5: ID | B5: 状态/招式 | C5: 行为与识别 | D5: 时间/数值建议 | E5: 设计目的与约束
A6: B00 | B6: 外观与角色 | C6: LowPolyHuman2.obj，1.35倍体型；TwoHandedGreatsword.fbx，双手握持。 | D6: 先用灰模，面向可辨。 | E6: 武器材质差异不影响命中；不要先花精力制作看台人群。
A7: B01 | B7: 待机/入场 | C7: 准备阶段不攻击；开战给清晰信号，短暂入场后开始第一招。 | D7: 开场安全缓冲1秒。 | E7: 避免开场直接扣血；计时起点统一。
A8: B02 | B8: 追击 | C8: 走向攻击距离；在选定攻击前可跟随目标。 | D8: 速度与距离由参数表控制。 | E8: 防止永久被风筝，但不靠瞬移和实时锁头命中。
A9: B03 | B9: 招式A：横扫 | C9: 举剑横摆后向前横扫，宽矩形预警对应原型箱体查询。 | D9: 当前实现：0.65 / 0.18 / 0.8秒，伤害18。 | E9: 教玩家读方向、一次正确翻滚和短反击；生效前锁定方向。
A10: B04 | B10: 招式B：延迟重砸 | C10: 双手举剑过头蓄力后下砸；落点不追踪玩家。 | D10: 当前实现：1.25 / 0.18 / 1.65秒，伤害32。 | E10: 克制见动作就滚，奖励观察延迟与重击反击；标记后停止追踪。
A11: B05 | B11: 招式C：短距突进 | C11: 肩膀前压，沿锁定方向冲出一段，末端停顿。 | D11: 当前实现：0.7 / 0.4 / 1.0秒，伤害24；速度15m/s，最大6m。 | E11: 防止持续后退成为万能解；冲刺路径不拐弯追踪，止于合法边界。
A12: B06 | B12: 动作选择 | C12: 近距离以横扫与重砸为主，拉远后可突进；限制同招连续重复。 | D12: 中距优先突进；禁止紧邻两次重复同招，随后追击。 | E12: 不要求复杂行为树；不能每帧重新决定攻击，避免看似随机跳动作。
A13: B07 | B13: 追踪锁定 | C13: 攻击预备早段可轻微转向，临近生效时固定。 | D13: 当前实现：从前摇开始锁定方向。 | E13: 玩家看到并利用可躲位置；不要视觉上躲开仍被转向命中。
A14: B08 | B14: 生命与时限 | C14: 固定单人生命与硬时限；不做动态难度。 | D14: 初值HP600、时限180秒，必须试玩校准。 | E14: 数值不是实测结论；先调动作，再调血量和时限。
A15: B09 | B15: 命中与硬直 | C15: 普通轻重击扣血有反馈，但不使Boss每次受击都中断。 | D15: P0不做复杂部位破坏或霸体层级。 | E15: 避免基础攻击永久锁死Boss；不能用强制硬直掩盖糟糕攻击节奏。
A16: B10 | B16: 死亡 | C16: 停止攻击判断，清除尚未结算的伤害；播放简短死亡或倒地。 | D16: 一个确定事件触发结算。 | E16: 箱子只生成一次；死亡不再发射攻击或触发额外空投。
... A19: B13 | B19: 后续支援兼容 | C19: 为未来控场道具保留可中断/已中断的单一入口。 | D19: P0主线不实现完整多人支援系统。 | E19: 先完成三招自身节奏；支援无法成为必须依赖的通关键。

Sheet 06_外围支援提案
A1: 外围搜集提案：可择机使用的控场支援
A2: P1待验证提案，不是用户已确认，不是P0必做。普通武器与道具在胜利后仍全部可搜集，支援物品也不例外。
A3: YOU ARE CHALLENGER / P0 单人验证 / v0.1 / 2026-09-06
A4: 返回目录
A5: ID | B5: 设计项 | C5: 建议规格 | D5: 为什么战中值得做 | E5: 限制/待验证
A6: SUP01 | B6: 核心矛盾 | C6: 武器不耗弹药，战后自由搜刮；仅增加普通装备数量不能保证玩家愿意在战中离开输出位。 | D6: 动机必须是改善当场胜率与通关用时，而非用封路或掉落过期制造焦虑。 | E6: 这是一项设计推论，不是已观测玩家数据。
A7: SUP02 | B7: 一个新增种类 | C7: 外围应援箱产出“擂台干扰器”：可消耗的控场支援道具，占一个现有道具栏。 | D7: 无需新增武器种类；同一物品可在救场、争取反击、准备救援时用。 | E7: 名称与外观可换为观众递来的喇叭/干扰器；不创造弹药或额外背包。
A8: SUP03 | B8: 基本作用 | C8: 建议对Boss造成一次短控场，打断当前可打断动作并产生约3秒明确恢复窗口；不直接造成固定伤害。 | D8: 挑战者获得喘息与输出机会，队友可以救援或进场集中攻击。 | E8: 效果长度与中断规则必须实测；不能连续锁死Boss。
A9: SUP04 | B9: 使用规则 | C9: 道具持有者在笼内或笼边支援交互点使用；消耗一件。 | D9: 外围玩家拿到后不必在危险期硬闯正门，支援位置与常规武器伤害规则分开。 | E9: P1建议标出有效范围；不可用状态不给扣物品，不能靠隐藏免疫吞道具。
A10: SUP05 | B10: 中断边界 | C10: P1首测允许中断预备动作与追击；正在生效的打击不被倒流取消，需等到下一可中断时机。 | D10: 早看出队友危险并提前使用，而非已经受伤后反悔。 | E10: UI显示可干扰状态；玩法不清楚时简化成下一段固定短收招，不堆复杂免疫。
A11: SUP06 | B11: 供应限制 | C11: 每场外围约2件作为起点，点位位置可变；不无限刷新，不通过Boss拖延刷永久金币。 | D11: 有限机会让队伍选择何时出场、何时使用。 | E11: 普通战后搜集不受限；未用道具可装入共享箱进入下一关。
A12: SUP07 | B12: 不能靠禁售后搜刮 | C12: 战后仍可拾取并继承干扰器；不设置道具过期、结算清除、强制装箱倒计时。 | D12: 留到战后获得的是下一关选择；战中用掉换的是本关时间、生存和救援窗口。 | E12: 由玩家决定保留或使用，不伪装成必须现在领取的奖励。
A13: SUP08 | B13: 反连续控制 | C13: 建议全队干扰有共享短冷却；本场有限供应，不能轮流无限打断。 | D13: 支援是一次战术机会，不取代挑战者操作。 | E13: 冷却数值待测，先用20秒；遗留跨关道具仍受同一限制。
A14: SUP09 | B14: 外围路线 | C14: 一段短、可见回笼方向的外围搜集线路；不设置独立副本、小怪战或收集多把钥匙。 | D14: 短期离开造成实际输出损失；Boss当前状态决定值不值得。 | E14: 往返距离要实测，路线太长就只剩固定跑腿。
A15: SUP10 | B15: 独立职责可切换 | C15: 不设专门搜集职业；谁道具栏有空、谁生命需要调整、谁更适合进场，由队伍选择。 | D15: 同一玩家在一场中可协战→搜集→支援→接班。 | E15: 不能让辅助玩家长期没有战斗参与感。
A16: SUP11 | B16: 单人与多人映射 | C16: 单人可在P0完成后通过空投试用同一物品；多人主要从外围应援箱取得。 | D16: 单人可测控场反馈和选择时机，多人仍需单独验证机会成本。 | E16: 不要把单人试用结果报告成外围机制已成立。
... A19: SUP14 | B19: 失败时怎么办 | C19: 若无人外出，先调整点位路程、取用时间和窗口质量；若固定跑腿最优，降低连续收益或供应。 | D19: 调整单一变量定位问题。 | E19: 不优先靠新增10种武器、禁止战后搜刮或必需钥匙来补救。

Sheet 07_物品与箱子
A1: 物品、战后自由搜刮与共享继承箱
A2: 原型物品保持少量。箱子是跨关取舍，不是战中补给仓。一个Boss只能验证装箱功能，不能证明长线配装乐趣。
A3: YOU ARE CHALLENGER / P0 单人验证 / v0.1 / 2026-09-06
A4: 返回目录
A5: ID | B5: 对象 | C5: 规格 | D5: 出现/使用时机 | E5: 继承与边界
A6: IT01 | B6: 双手大剑 | C6: 一把武器，轻击和重击；不耗弹药，不做耐久。 | D6: 准备阶段默认装备；可用占位外观。 | E6: 可装箱占一格；放下后可再拾；武器栏只能一把。
A7: IT02 | B7: 恢复药 | C7: 一次性恢复30生命，建议未满生命时使用。 | D7: 开局少量携带、空投、战后外围可拾取。 | E7: 占一道具栏；未用可装箱；已消耗不恢复。
A8: IT03 | B8: 精力饮料 | C8: 一次性恢复50精力，满值不超上限。 | D8: 随机空投或场地物资。 | E8: 占一道具栏；无隐藏额外储备数量。
A9: IT04 | B9: 擂台干扰器 | C9: P1候选控场支援物品，不纳入P0主线完成条件。 | D9: 多人外围应援箱；单人可选调试空投测试。 | E9: 属于普通可继承道具，战后可继续拾取，未用可入箱。
A10: IT05 | B10: 初始装备 | C10: 本轮开局武器与道具不享有额外自动继承资格。 | D10: 开始新一轮时由验证配置发放。 | E10: “只有箱内跨关”目前为解释性提案，结束时明确提示。
A11: CH01 | B11: 中央共享箱 | C11: 实体交互对象＋两格UI，单人两格。 | D11: Boss被击败并停止战斗后在笼中央出现。 | E11: 战中不存在；结算只生成一次；失败不生成胜利奖励箱。
A12: CH02 | B12: 容量 | C12: 开局玩家数×2，P0开局玩家数=1。 | D12: 后续联机建议开局锁定人数。 | E12: 倒地、离笼不影响容量；中途加入规则不在P0。
A13: CH03 | B13: 存取 | C13: 玩家随身物品存入，箱中物品取出到合法栏位；一件一格。 | D13: 胜利后可反复整理，不限制时间。 | E13: 箱满拒绝并说明；不让武器落到道具栏；不凭空复制。
A14: CH04 | B14: 战后普通搜刮 | C14: 保留未搜物资和地面掉落，允许离开八角笼拾取。 | D14: 直到玩家主动确认离开。 | E14: 不冻结Boss死前物品清单，不清空空投，不锁外围。
A15: CH05 | B15: 随身未入箱 | C15: 结束前展示将被舍弃的随身物品，可取消返回继续装箱。 | D15: 玩家主动结算确认。 | E15: 不偷偷自动带入下一关，也不在未确认前删除。
A16: CH06 | B16: 物品状态 | C16: 以稳定item_id和实例状态保存；无弹药字段。 | D16: 建立携带/箱子/地面唯一归属。 | E16: 基础原型不加品质、耐久、词条与堆叠。
... A19: CH09 | B19: 空武器保底 | C19: 建议简易徒手或始终允许重新拾回大剑，防止所有武器装箱后无法操作。 | D19: 战后无需攻击，主要作为调试与后续关卡保底。 | E19: 不因此新增复杂拳击战斗体系。

Sheet 08_开发任务
A1: 按可玩结果拆分的开发任务
A2: 状态描述是计划台账。未读取实际代码或没有验收证据时，不得改成“完成”。不在本次任务中自动创建GitHub Issue。
A3: YOU ARE CHALLENGER / P0 单人验证 / v0.1 / 2026-09-06
A4: 返回目录
A5: ID | B5: 阶段 | C5: 任务 | D5: 范围 | E5: 依赖 | F5: 完成标准 | G5: 状态 | H5: 责任角色
A6: T01 | B6: P0-1 | C6: 核对仓库与建立最小场景 | D6: Godot 4.7.2；平地场地，LowPolyHuman2 双手大剑角色与 Boss。 | E6: 无 | F6: 可运行单人场景，无需观众AI。 | G6: 完成 | H6: 程序员
A7: T02 | B7: P0-1 | C7: 第三人称移动与镜头 | D7: 移动、转向、镜头遮挡处理、笼边观察。 | E7: T01 | F7: 沿边界移动仍能看清玩家与Boss预备动作。 | G7: 完成 | H7: 程序员
A8: T03 | B8: P0-1 | C8: 大剑轻重攻击 | D8: 两种时序、明确命中体积、一次攻击单次结算。 | E8: T02 | F8: 调试可核对命中，无穿墙多段重复扣血。 | G8: 完成 | H8: 程序员
A9: T04 | B9: P0-1 | C9: 翻滚与精力 | D9: 无敌时间窗、消耗、恢复、不足反馈。 | E9: T02 | F9: 早滚/正确滚/晚滚有差异，无法永久无敌。 | G9: 完成 | H9: 程序员
A10: T05 | B10: P0-1 | C10: 生命、受击和状态 | D10: 伤害反馈，攻击/翻滚/倒地优先级。 | E10: T03,T04 | F10: 受击一次扣对应生命，倒地停止攻击。 | G10: 完成 | H10: 程序员
A11: T06 | B11: P0-2 | C11: Boss状态与第一招 | D11: 追击、横扫、锁定方向、收招。 | E11: T05 | F11: 不用道具可反复读招、躲招和反击。 | G11: 完成 | H11: 程序员
A12: T07 | B12: P0-2 | C12: Boss另外两招 | D12: 延迟重砸与短距突进；限制重复。 | E12: T06 | F12: 提前滚与无限后退都不是通用无脑解。 | G12: 完成 | H12: 程序员
A13: T08 | B13: P0-2 | C13: 动作反馈与首轮调参 | D13: 双手握持、攻击时钟、三招动作和反馈已实现；首轮自动检查通过，手感待真人复验。 | E13: T07 | F13: 受伤原因可解释；先修动作再改数值。 | G13: 完成 | H13: 策划＋程序员
A14: T09 | B14: P0-3 | C14: 准备、时限与胜败 | D14: 开始按钮、挑战者禁出、胜利停止伤害、超时失败。 | E14: T08 | F14: 三种结果分支互斥，同局只结算一次。 | G14: 完成 | H14: 程序员
A15: T10 | B15: P0-3 | C15: 整轮两次单人复活 | D15: 同Boss保血量，时钟继续；第三次倒地失败。 | E15: T09 | F15: 仅新一轮重置两次，复起落点和保护正常。 | G15: 完成 | H15: 程序员
A16: T11 | B16: P0-3 | C16: 栏位、两道具与空投 | D16: 一武器两道具，恢复药/精力饮料，合法落点随机空投。 | E16: T09 | F16: 可替换与消耗，满栏明确，战后未拾物保留。 | G16: 完成 | H16: 程序员
... A24: T19 | B24: P2 | C24: 跨Boss与长期系统 | D24: 真实第二Boss、赌约、计分金币、局外选装、隐藏Boss。 | E24: P1假设通过 | F24: 另行收敛范围，不自动加入P0。 | G24: 后续 | H24: 策划

Sheet 09_验收用例
A1: 核心验收用例
A2: 优先正常可玩路径与少量高价值边界。不扩展为安全审计或大量无关压力测试；具体观察必须在执行后填写。
A3: YOU ARE CHALLENGER / P0 单人验证 / v0.1 / 2026-09-06
A4: 返回目录
A5: ID | B5: 主题 | C5: 步骤 | D5: 预期 | E5: 阶段 | F5: 结果 | G5: 观察/缺陷
A6: QA01 | B6: 移动镜头 | C6: 沿笼边移动并持续转镜头；靠近Boss。 | D6: 人物与Boss预备动作可见；无遮挡死角导致无法躲招。 | E6: P0-1 | F6: 未测 | G6: 自动镜头/输入检查通过；用户反馈Boss出现在角色头上，已增加落地修复与回归，真人镜头复验待做。
A7: QA02 | B7: 一次命中 | C7: 用单次轻击同时接触Boss多个碰撞体。 | D7: 本次攻击只扣一次配置伤害。 | E7: P0-1 | F7: 通过 | G7: 自动图形检查：同次轻击对重叠受击区只扣22生命。
A8: QA03 | B8: 轻重取舍 | C8: 分别在横扫和重砸收招期使用轻击/重击。 | D8: 至少存在轻击安全而重击有风险的窗口。 | E8: P0-2 | F8: 未测 | G8: 自动时序验证：横扫收招0.8秒，重砸收招1.65秒；真人轻重取舍待测。
A9: QA04 | B9: 无敌窗口 | C9: 在同一Boss招式前提前、准确、过晚翻滚。 | D9: 仅无敌窗口重叠生效伤害时规避；整段翻滚并非都无敌。 | E9: P0-1 | F9: 通过 | G9: 自动检查：提前/准确/过晚翻滚与无敌区间0.08–0.28秒一致。
A10: QA05 | B10: 精力耗尽 | C10: 连续翻滚到不足，再尝试翻滚和普通移动。 | D10: 精力不负数，无法免费攻击或翻滚；仍可走位，恢复足够精力后攻击。 | E10: P0-1 | F10: 通过 | G10: 自动检查：精力不足不能轻重击或翻滚；仍可移动与恢复。
A11: QA06 | B11: Boss方向锁定 | C11: 在重砸前摇末段侧移。 | D11: Boss不在生效瞬间转向命中已离开范围的玩家。 | E11: P0-2 | F11: 通过 | G11: 自动检查：三招前摇开始后方向锁定，侧移不被瞬时转向命中。
A12: QA07 | B12: 基础可通关 | C12: 不使用恢复药和特殊道具，熟悉后尝试击败Boss。 | D12: 允许纯基础操作取胜；不存在必须等某空投的阶段。 | E12: P0-2 | F12: 通过 | G12: 自动完整对练图形模式：种子7与42获胜；种子123在Boss余24生命时失败。不是真人试玩结论。
A13: QA08 | B13: 单人两次复活 | C13: 连续经历三次倒地且不击杀Boss。 | D13: 前两次各扣一次复活并恢复；第三次失败。 | E13: P0-3 | F13: 通过 | G13: 图形自动验收：前两次倒地各扣一次机会；第三次失败。
A14: QA09 | B14: 复活不重开 | C14: 伤害Boss后倒地再复起。 | D14: Boss残余生命保留，计时未重置，复活余量减少。 | E14: P0-3 | F14: 通过 | G14: 图形自动验收：Boss从600扣到480后倒地复起，仍为480；时钟继续，复活余量减少。
A15: QA10 | B15: 时间到点 | C15: 不击败Boss，等待硬时限。 | D15: 只结算超时失败，停止AI和伤害，不生成胜利箱。 | E15: P0-3 | F15: 通过 | G15: 图形自动验收：主动战斗及倒地复起期间超时均失败；停止AI/伤害/新空投，无胜利箱。
A16: QA11 | B16: 空投合法性 | C16: 观察多轮空投并拾取。 | D16: 在可达笼内落地，有提示，未拾道具在胜利后保留。 | E16: P0-3 | F16: 通过 | G16: 图形自动验收：空投在半径3–8m内预告后落地；每轮最多3件，胜利后未拾物仍保留。
... A27: QA22 | B27: 数据真实性 | C27: 查看本表状态和试玩记录。 | D27: 未实际测试的状态是未测，观察结果留空，不使用假完成率。 | E27: P0验收 | F27: 通过 | G27: 表格复核：自动检查注明来源，真人镜头与轻重取舍仍未测；PT01只记录真实用户缺陷反馈。

Sheet 10_试玩记录
A1: 试玩记录：只填真实观察
A2: 蓝色列为输入；命中归因率=可解释受击次数/总受击次数。空白表示未测，不代表零；不从小样本推导统计显著性。
A3: YOU ARE CHALLENGER / P0 单人验证 / v0.1 / 2026-09-06
A4: 返回目录
A5: ID | B5: 测试者/版本 | C5: 结果 | D5: 战斗秒数 | E5: 总受击次数 | F5: 可解释受击次数 | G5: 使用复活 | H5: 轻/重击选择备注 | I5: 空投选择理由 | J5: 命中归因率 | K5: 主要问题 | L5: 下一次只改一项
A6: PT01 | B6: 用户反馈 / P0-2 | J6: =IF(OR(D6="",E6=""),"",IF(E6>0,F6/E6,"")) | K6: Boss出现在角色头上；要求起身收势改为0.05秒。 | L6: 修复落地并缩短起身；真人复验待补。
A7: PT02 | J7: =IF(OR(D7="",E7=""),"",IF(E7>0,F7/E7,""))
A8: PT03 | J8: =IF(OR(D8="",E8=""),"",IF(E8>0,F8/E8,""))
A9: PT04 | J9: =IF(OR(D9="",E9=""),"",IF(E9>0,F9/E9,""))
A10: PT05 | J10: =IF(OR(D10="",E10=""),"",IF(E10>0,F10/E10,""))
A11: PT06 | J11: =IF(OR(D11="",E11=""),"",IF(E11>0,F11/E11,""))
A12: PT07 | J12: =IF(OR(D12="",E12=""),"",IF(E12>0,F12/E12,""))
A13: PT08 | J13: =IF(OR(D13="",E13=""),"",IF(E13>0,F13/E13,""))
A14: PT09 | J14: =IF(OR(D14="",E14=""),"",IF(E14>0,F14/E14,""))
A15: PT10 | J15: =IF(OR(D15="",E15=""),"",IF(E15>0,F15/E15,""))
A16: PT11 | J16: =IF(OR(D16="",E16=""),"",IF(E16>0,F16/E16,""))
A17: PT12 | J17: =IF(OR(D17="",E17=""),"",IF(E17>0,F17/E17,""))
A18: PT13 | J18: =IF(OR(D18="",E18=""),"",IF(E18>0,F18/E18,""))
... A25: PT20 | J25: =IF(OR(D25="",E25=""),"",IF(E25>0,F25/E25,""))

Sheet 11_参数与进度
A1: 调参入口与验证进度
A2: 蓝色为可调输入，绿色为用户约束取值，黑色为公式。所有战斗初值只用于开始测试，不是效果承诺或实测结果。
A3: YOU ARE CHALLENGER / P0 单人验证 / v0.1 / 2026-09-06
A4: 返回目录
A5: ID | B5: 参数 | C5: 值 | D5: 单位 | E5: 来源/性质 | F5: 解释
A6: P01 | B6: 单人开局人数 | C6: 1 | D6: 人 | E6: 用户规则在P0的取值 | F6: 仅用于箱容量；不是正式人数上限
A7: P02 | B7: 每玩家箱格 | C7: 2 | D7: 格/人 | E7: 用户确认 | F7: 箱容量=人数×2
A8: P03 | B8: 共享箱格 | C8: =C6*C7 -> 2 | D8: 格 | E8: 公式 | F8: 根据开局人数和每人格数计算
A9: P04 | B9: 每人武器栏 | C9: 1 | D9: 栏 | E9: 用户确认 | F9: 不叠加隐藏副武器
A10: P05 | B10: 每人道具栏 | C10: 2 | D10: 栏 | E10: 用户确认 | F10: 不设额外背包
A11: P06 | B11: 整轮复活机会 | C11: 2 | D11: 次 | E11: 用户确认 | F11: 新一轮才重置
A12: P07 | B12: 生命上限 | C12: 100 | D12: 生命 | E12: 策划测试初值 | F12: 未经过真实试玩校准
A13: P08 | B13: 精力上限 | C13: 100 | D13: 精力 | E13: 策划测试初值 | F13: 与翻滚成本共同调试
A14: P09 | B14: 普通移动速度 | C14: 5.5 | D14: 场景单位/秒 | E14: 策划测试初值 | F14: 随实际角色/场地尺度修正
A15: P10 | B15: 翻滚精力成本 | C15: 25 | D15: 精力 | E15: 策划测试初值 | F15: 不能通过负数精力免费执行
A16: P11 | B16: 翻滚动作时长 | C16: 0.55 | D16: 秒 | E16: 策划测试初值 | F16: 与无敌区间分离
A17: P12 | B17: 无敌起点 | C17: 0.08 | D17: 秒 | E17: 策划测试初值 | F17: 相对翻滚动作开始
A18: P13 | B18: 无敌终点 | C18: 0.28 | D18: 秒 | E18: 策划测试初值 | F18: 不得超过动作总长
A19: P14 | B19: 无敌持续 | C19: =C18-C17 -> 0.2 | D19: 秒 | E19: 公式 | F19: 起止差，非整段无敌
A20: P15 | B20: 精力恢复延迟 | C20: 0.7 | D20: 秒 | E20: 策划测试初值 | F20: 停止耗精力后开始恢复
A21: P16 | B21: 精力恢复速度 | C21: 25 | D21: 精力/秒 | E21: 策划测试初值 | F21: 普通移动可恢复
A22: P17 | B22: 满精力可连续支付翻滚 | C22: =INT(C13/C15) -> 4 | D22: 次 | E22: 公式 | F22: 只计算成本，不包含期间恢复
A23: P18 | B23: 轻击伤害 | C23: 22 | D23: 生命 | E23: 策划测试初值 | F23: 先校准时序与有效命中率
A24: P19 | B24: 轻击前摇 | C24: 0.25 | D24: 秒 | E24: 策划测试初值 | F24: 单段，不制作复杂连段
A25: P20 | B25: 轻击生效 | C25: 0.12 | D25: 秒 | E25: 策划测试初值 | F25: 每攻击对同Boss一次结算
A26: P21 | B26: 轻击收招 | C26: 0.38 | D26: 秒 | E26: 策划测试初值 | F26: 禁止免费无限取消
A27: P22 | B27: 轻击总时长 | C27: =SUM(C24:C26) -> 0.75 | D27: 秒 | E27: 公式 | F27: 前摇＋生效＋收招
A28: P23 | B28: 重击伤害 | C28: 48 | D28: 生命 | E28: 策划测试初值 | F28: 需较大收招窗口
A29: P24 | B29: 重击精力成本 | C29: 20 | D29: 精力 | E29: 策划测试初值 | F29: 轻击也消耗10精力，已按用户反馈修改。
A30: P25 | B30: 重击前摇 | C30: 0.6 | D30: 秒 | E30: 策划测试初值 | F30: 不得到生效前随意吸附转向
A31: P26 | B31: 重击生效 | C31: 0.18 | D31: 秒 | E31: 策划测试初值 | F31: 一次攻击一次结算
A32: P27 | B32: 重击收招 | C32: 0.6 | D32: 秒 | E32: 策划测试初值 | F32: 攻击承诺的一部分
A33: P28 | B33: 重击总时长 | C33: =SUM(C30:C32) -> 1.38 | D33: 秒 | E33: 公式 | F33: 前摇＋生效＋收招
A34: P29 | B34: Boss单人生命 | C34: 600 | D34: 生命 | E34: 策划测试初值 | F34: 非实测最终平衡值
A35: P30 | B35: Boss战硬时限 | C35: 180 | D35: 秒 | E35: 策划测试初值 | F35: 超时失败建议
A36: P31 | B36: 恢复药恢复量 | C36: 30 | D36: 生命 | E36: 策划测试初值 | F36: 使用一次消耗一件
A37: P32 | B37: 精力饮料恢复量 | C37: 50 | D37: 精力 | E37: 策划测试初值 | F37: 不超上限
A38: P33 | B38: 单人复起生命比例 | C38: 0.5 | D38: 比例 | E38: 策划测试初值 | F38: 复起保留Boss残血与战斗用时
A39: P34 | B39: 单人复起生命 | C39: =C12*C38 -> 50 | D39: 生命 | E39: 公式 | F39: 生命上限×复起比例
A40: P35 | B40: P1支援控场时间 | C40: 3 | D40: 秒 | E40: 未来实验初值 | F40: 不属于P0必须功能
...

Sheet 12_决策与变更
A1: 待决策项、覆盖记录与文档维护
A2: P0采用的解释性选择在此明示。无需等待所有长期决策才能开发角色与Boss，但不能把未确认项写成永久产品规则。
A3: YOU ARE CHALLENGER / P0 单人验证 / v0.1 / 2026-09-06
A4: 返回目录
A5: ID | B5: 主题 | C5: 当前处理 | D5: 属性 | E5: 何时需要决定
A6: D01 | B6: 中央箱时机 | C6: 只在Boss胜利结束后中央出现，删除旧战中存取方案。 | D6: 用户最新确认 | E6: 立即按此修改文档与验收
A7: D02 | B7: 战后搜刮 | C7: 无限时自由搜刮，删除Boss死亡瞬间冻结地面物品方案。 | D7: 用户最新确认 | E7: 立即按此修改文档与验收
A8: D03 | B8: 验证规模 | C8: 单人、一个Boss，删除两常规Boss＋隐藏Boss作为首版要求。 | D8: 用户最新确认 | E8: 立即收敛任务
A9: D04 | B9: 只有箱内跨关 | C9: P0只保存箱内物品到测试快照；未入箱随身及地面物品在主动确认后舍弃，取消不删除。 | D9: 本次P0实现约定 | E9: 真实跨Boss与跨轮规则仍留后续阶段
A10: D05 | B10: 支援玩法 | C10: 外围应援箱提供控场道具，战后仍可拿并继承。 | D10: 策划提案，待验证 | E10: P1实验前
A11: D06 | B11: 多人攻击边界 | C11: 建议常规武器笼外不伤Boss，控场支援有明确例外。 | D11: 策划提案 | E11: P1外围实验前
A12: D07 | B12: 接班选取规则 | C12: 立即选人已确定，随机/轮转/优先级未确定。 | D12: 用户规则尚未细化 | E12: P1救援交接前
A13: D08 | B13: 多人上限 | C13: 不擅定正式上限，先双人验证。 | D13: 待决策 | E13: P1联机设计前
A14: D09 | B14: 赌约范围与下注 | C14: 个人/全队、健康限制语义、扣不扣本金未定。 | D14: 待决策 | E14: P2赌约前
A15: D10 | B15: 局外成长类型 | C15: 横向选装还是永久属性未定；P0不做永久属性树。 | D15: 待决策 | E15: P2经济前
A16: D11 | B16: 积分门槛与多人系数 | C16: 不能使用P0单人一Boss结果假设已平衡完整Boss Rush。 | D16: 待验证 | E16: 真实连战与P1结果完成后
... A29: D24 | B29: 2026-09-07 修复后回归 | C29: 角色78、Boss45、动作27、流程75项通过，默认启动11项通过。60秒贴身检查及67.75秒完整自动战斗通过。 | D29: 自动验证，非真人试玩 | E29: 无缓存副本首次导入无报错，手感验收仍待真人
